[ 2024-09-09 11:39:46,429 ] 97 werkzeug - INFO - [31m[1mWARNING: This is a development server. Do not use it in a production deployment. Use a production WSGI server instead.[0m
 * Running on all addresses (0.0.0.0)
 * Running on http://127.0.0.1:8080
 * Running on http://192.168.254.74:8080
[ 2024-09-09 11:39:46,429 ] 97 werkzeug - INFO - [33mPress CTRL+C to quit[0m
[ 2024-09-09 11:40:52,665 ] 97 werkzeug - INFO - 127.0.0.1 - - [09/Sep/2024 11:40:52] "GET / HTTP/1.1" 200 -
[ 2024-09-09 11:40:53,375 ] 97 werkzeug - INFO - 127.0.0.1 - - [09/Sep/2024 11:40:53] "[33mGET /favicon.ico HTTP/1.1[0m" 404 -
[ 2024-09-09 11:47:41,956 ] 97 werkzeug - INFO - 127.0.0.1 - - [09/Sep/2024 11:47:41] "GET /predictdata HTTP/1.1" 200 -
[ 2024-09-09 11:48:06,931 ] 838 app - ERROR - Exception on /predictdata [POST]
Traceback (most recent call last):
  File "C:\Users\ssune\Documents\GitHub\Complete-Data-Science-With-Machine-Learning-And-NLP-2024\mlProject\src\pipeline\predict_pipeline.py", line 18, in predict
    data_scaled=preprocessor.transform(features)
  File "C:\Users\ssune\Documents\GitHub\learngenAI310\lib\site-packages\sklearn\utils\_set_output.py", line 313, in wrapped
    data_to_wrap = f(self, X, *args, **kwargs)
  File "C:\Users\ssune\Documents\GitHub\learngenAI310\lib\site-packages\sklearn\compose\_column_transformer.py", line 1076, in transform
    Xs = self._call_func_on_transformers(
  File "C:\Users\ssune\Documents\GitHub\learngenAI310\lib\site-packages\sklearn\compose\_column_transformer.py", line 885, in _call_func_on_transformers
    return Parallel(n_jobs=self.n_jobs)(jobs)
  File "C:\Users\ssune\Documents\GitHub\learngenAI310\lib\site-packages\sklearn\utils\parallel.py", line 74, in __call__
    return super().__call__(iterable_with_config)
  File "C:\Users\ssune\Documents\GitHub\learngenAI310\lib\site-packages\joblib\parallel.py", line 1918, in __call__
    return output if self.return_generator else list(output)
  File "C:\Users\ssune\Documents\GitHub\learngenAI310\lib\site-packages\joblib\parallel.py", line 1847, in _get_sequential_output
    res = func(*args, **kwargs)
  File "C:\Users\ssune\Documents\GitHub\learngenAI310\lib\site-packages\sklearn\utils\parallel.py", line 136, in __call__
    return self.function(*args, **kwargs)
  File "C:\Users\ssune\Documents\GitHub\learngenAI310\lib\site-packages\sklearn\pipeline.py", line 1290, in _transform_one
    res = transformer.transform(X, **params.transform)
  File "C:\Users\ssune\Documents\GitHub\learngenAI310\lib\site-packages\sklearn\pipeline.py", line 903, in transform
    Xt = transform.transform(Xt, **routed_params[name].transform)
  File "C:\Users\ssune\Documents\GitHub\learngenAI310\lib\site-packages\sklearn\utils\_set_output.py", line 313, in wrapped
    data_to_wrap = f(self, X, *args, **kwargs)
  File "C:\Users\ssune\Documents\GitHub\learngenAI310\lib\site-packages\sklearn\preprocessing\_encoders.py", line 1033, in transform
    if self._drop_idx_after_grouping is not None:
AttributeError: 'OneHotEncoder' object has no attribute '_drop_idx_after_grouping'

During handling of the above exception, another exception occurred:

Traceback (most recent call last):
  File "C:\Users\ssune\Documents\GitHub\learngenAI310\lib\site-packages\flask\app.py", line 1473, in wsgi_app
    response = self.full_dispatch_request()
  File "C:\Users\ssune\Documents\GitHub\learngenAI310\lib\site-packages\flask\app.py", line 882, in full_dispatch_request
    rv = self.handle_user_exception(e)
  File "C:\Users\ssune\Documents\GitHub\learngenAI310\lib\site-packages\flask\app.py", line 880, in full_dispatch_request
    rv = self.dispatch_request()
  File "C:\Users\ssune\Documents\GitHub\learngenAI310\lib\site-packages\flask\app.py", line 865, in dispatch_request
    return self.ensure_sync(self.view_functions[rule.endpoint])(**view_args)  # type: ignore[no-any-return]
  File "C:\Users\ssune\Documents\GitHub\Complete-Data-Science-With-Machine-Learning-And-NLP-2024\mlProject\app.py", line 37, in predict_datapoint
    results=predict_pipeline.predict(pred_df)
  File "C:\Users\ssune\Documents\GitHub\Complete-Data-Science-With-Machine-Learning-And-NLP-2024\mlProject\src\pipeline\predict_pipeline.py", line 23, in predict
    raise CustomException(e,sys)
src.exception.CustomException: Error occured in python script name [C:\Users\ssune\Documents\GitHub\Complete-Data-Science-With-Machine-Learning-And-NLP-2024\mlProject\src\pipeline\predict_pipeline.py] line number [18] error message['OneHotEncoder' object has no attribute '_drop_idx_after_grouping']
[ 2024-09-09 11:48:06,985 ] 97 werkzeug - INFO - 127.0.0.1 - - [09/Sep/2024 11:48:06] "[35m[1mPOST /predictdata HTTP/1.1[0m" 500 -
[ 2024-09-09 11:48:46,365 ] 838 app - ERROR - Exception on /predictdata [POST]
Traceback (most recent call last):
  File "C:\Users\ssune\Documents\GitHub\Complete-Data-Science-With-Machine-Learning-And-NLP-2024\mlProject\src\pipeline\predict_pipeline.py", line 18, in predict
    data_scaled=preprocessor.transform(features)
  File "C:\Users\ssune\Documents\GitHub\learngenAI310\lib\site-packages\sklearn\utils\_set_output.py", line 313, in wrapped
    data_to_wrap = f(self, X, *args, **kwargs)
  File "C:\Users\ssune\Documents\GitHub\learngenAI310\lib\site-packages\sklearn\compose\_column_transformer.py", line 1076, in transform
    Xs = self._call_func_on_transformers(
  File "C:\Users\ssune\Documents\GitHub\learngenAI310\lib\site-packages\sklearn\compose\_column_transformer.py", line 885, in _call_func_on_transformers
    return Parallel(n_jobs=self.n_jobs)(jobs)
  File "C:\Users\ssune\Documents\GitHub\learngenAI310\lib\site-packages\sklearn\utils\parallel.py", line 74, in __call__
    return super().__call__(iterable_with_config)
  File "C:\Users\ssune\Documents\GitHub\learngenAI310\lib\site-packages\joblib\parallel.py", line 1918, in __call__
    return output if self.return_generator else list(output)
  File "C:\Users\ssune\Documents\GitHub\learngenAI310\lib\site-packages\joblib\parallel.py", line 1847, in _get_sequential_output
    res = func(*args, **kwargs)
  File "C:\Users\ssune\Documents\GitHub\learngenAI310\lib\site-packages\sklearn\utils\parallel.py", line 136, in __call__
    return self.function(*args, **kwargs)
  File "C:\Users\ssune\Documents\GitHub\learngenAI310\lib\site-packages\sklearn\pipeline.py", line 1290, in _transform_one
    res = transformer.transform(X, **params.transform)
  File "C:\Users\ssune\Documents\GitHub\learngenAI310\lib\site-packages\sklearn\pipeline.py", line 903, in transform
    Xt = transform.transform(Xt, **routed_params[name].transform)
  File "C:\Users\ssune\Documents\GitHub\learngenAI310\lib\site-packages\sklearn\utils\_set_output.py", line 313, in wrapped
    data_to_wrap = f(self, X, *args, **kwargs)
  File "C:\Users\ssune\Documents\GitHub\learngenAI310\lib\site-packages\sklearn\preprocessing\_encoders.py", line 1033, in transform
    if self._drop_idx_after_grouping is not None:
AttributeError: 'OneHotEncoder' object has no attribute '_drop_idx_after_grouping'

During handling of the above exception, another exception occurred:

Traceback (most recent call last):
  File "C:\Users\ssune\Documents\GitHub\learngenAI310\lib\site-packages\flask\app.py", line 1473, in wsgi_app
    response = self.full_dispatch_request()
  File "C:\Users\ssune\Documents\GitHub\learngenAI310\lib\site-packages\flask\app.py", line 882, in full_dispatch_request
    rv = self.handle_user_exception(e)
  File "C:\Users\ssune\Documents\GitHub\learngenAI310\lib\site-packages\flask\app.py", line 880, in full_dispatch_request
    rv = self.dispatch_request()
  File "C:\Users\ssune\Documents\GitHub\learngenAI310\lib\site-packages\flask\app.py", line 865, in dispatch_request
    return self.ensure_sync(self.view_functions[rule.endpoint])(**view_args)  # type: ignore[no-any-return]
  File "C:\Users\ssune\Documents\GitHub\Complete-Data-Science-With-Machine-Learning-And-NLP-2024\mlProject\app.py", line 37, in predict_datapoint
    results=predict_pipeline.predict(pred_df)
  File "C:\Users\ssune\Documents\GitHub\Complete-Data-Science-With-Machine-Learning-And-NLP-2024\mlProject\src\pipeline\predict_pipeline.py", line 23, in predict
    raise CustomException(e,sys)
src.exception.CustomException: Error occured in python script name [C:\Users\ssune\Documents\GitHub\Complete-Data-Science-With-Machine-Learning-And-NLP-2024\mlProject\src\pipeline\predict_pipeline.py] line number [18] error message['OneHotEncoder' object has no attribute '_drop_idx_after_grouping']
[ 2024-09-09 11:48:46,374 ] 97 werkzeug - INFO - 127.0.0.1 - - [09/Sep/2024 11:48:46] "[35m[1mPOST /predictdata HTTP/1.1[0m" 500 -
[ 2024-09-09 11:49:05,152 ] 838 app - ERROR - Exception on /predictdata [POST]
Traceback (most recent call last):
  File "C:\Users\ssune\Documents\GitHub\Complete-Data-Science-With-Machine-Learning-And-NLP-2024\mlProject\src\pipeline\predict_pipeline.py", line 18, in predict
    data_scaled=preprocessor.transform(features)
  File "C:\Users\ssune\Documents\GitHub\learngenAI310\lib\site-packages\sklearn\utils\_set_output.py", line 313, in wrapped
    data_to_wrap = f(self, X, *args, **kwargs)
  File "C:\Users\ssune\Documents\GitHub\learngenAI310\lib\site-packages\sklearn\compose\_column_transformer.py", line 1076, in transform
    Xs = self._call_func_on_transformers(
  File "C:\Users\ssune\Documents\GitHub\learngenAI310\lib\site-packages\sklearn\compose\_column_transformer.py", line 885, in _call_func_on_transformers
    return Parallel(n_jobs=self.n_jobs)(jobs)
  File "C:\Users\ssune\Documents\GitHub\learngenAI310\lib\site-packages\sklearn\utils\parallel.py", line 74, in __call__
    return super().__call__(iterable_with_config)
  File "C:\Users\ssune\Documents\GitHub\learngenAI310\lib\site-packages\joblib\parallel.py", line 1918, in __call__
    return output if self.return_generator else list(output)
  File "C:\Users\ssune\Documents\GitHub\learngenAI310\lib\site-packages\joblib\parallel.py", line 1847, in _get_sequential_output
    res = func(*args, **kwargs)
  File "C:\Users\ssune\Documents\GitHub\learngenAI310\lib\site-packages\sklearn\utils\parallel.py", line 136, in __call__
    return self.function(*args, **kwargs)
  File "C:\Users\ssune\Documents\GitHub\learngenAI310\lib\site-packages\sklearn\pipeline.py", line 1290, in _transform_one
    res = transformer.transform(X, **params.transform)
  File "C:\Users\ssune\Documents\GitHub\learngenAI310\lib\site-packages\sklearn\pipeline.py", line 903, in transform
    Xt = transform.transform(Xt, **routed_params[name].transform)
  File "C:\Users\ssune\Documents\GitHub\learngenAI310\lib\site-packages\sklearn\utils\_set_output.py", line 313, in wrapped
    data_to_wrap = f(self, X, *args, **kwargs)
  File "C:\Users\ssune\Documents\GitHub\learngenAI310\lib\site-packages\sklearn\preprocessing\_encoders.py", line 1033, in transform
    if self._drop_idx_after_grouping is not None:
AttributeError: 'OneHotEncoder' object has no attribute '_drop_idx_after_grouping'

During handling of the above exception, another exception occurred:

Traceback (most recent call last):
  File "C:\Users\ssune\Documents\GitHub\learngenAI310\lib\site-packages\flask\app.py", line 1473, in wsgi_app
    response = self.full_dispatch_request()
  File "C:\Users\ssune\Documents\GitHub\learngenAI310\lib\site-packages\flask\app.py", line 882, in full_dispatch_request
    rv = self.handle_user_exception(e)
  File "C:\Users\ssune\Documents\GitHub\learngenAI310\lib\site-packages\flask\app.py", line 880, in full_dispatch_request
    rv = self.dispatch_request()
  File "C:\Users\ssune\Documents\GitHub\learngenAI310\lib\site-packages\flask\app.py", line 865, in dispatch_request
    return self.ensure_sync(self.view_functions[rule.endpoint])(**view_args)  # type: ignore[no-any-return]
  File "C:\Users\ssune\Documents\GitHub\Complete-Data-Science-With-Machine-Learning-And-NLP-2024\mlProject\app.py", line 37, in predict_datapoint
    results=predict_pipeline.predict(pred_df)
  File "C:\Users\ssune\Documents\GitHub\Complete-Data-Science-With-Machine-Learning-And-NLP-2024\mlProject\src\pipeline\predict_pipeline.py", line 23, in predict
    raise CustomException(e,sys)
src.exception.CustomException: Error occured in python script name [C:\Users\ssune\Documents\GitHub\Complete-Data-Science-With-Machine-Learning-And-NLP-2024\mlProject\src\pipeline\predict_pipeline.py] line number [18] error message['OneHotEncoder' object has no attribute '_drop_idx_after_grouping']
[ 2024-09-09 11:49:05,153 ] 97 werkzeug - INFO - 127.0.0.1 - - [09/Sep/2024 11:49:05] "[35m[1mPOST /predictdata HTTP/1.1[0m" 500 -
[ 2024-09-09 11:49:21,360 ] 838 app - ERROR - Exception on /predictdata [POST]
Traceback (most recent call last):
  File "C:\Users\ssune\Documents\GitHub\Complete-Data-Science-With-Machine-Learning-And-NLP-2024\mlProject\src\pipeline\predict_pipeline.py", line 18, in predict
    data_scaled=preprocessor.transform(features)
  File "C:\Users\ssune\Documents\GitHub\learngenAI310\lib\site-packages\sklearn\utils\_set_output.py", line 313, in wrapped
    data_to_wrap = f(self, X, *args, **kwargs)
  File "C:\Users\ssune\Documents\GitHub\learngenAI310\lib\site-packages\sklearn\compose\_column_transformer.py", line 1076, in transform
    Xs = self._call_func_on_transformers(
  File "C:\Users\ssune\Documents\GitHub\learngenAI310\lib\site-packages\sklearn\compose\_column_transformer.py", line 885, in _call_func_on_transformers
    return Parallel(n_jobs=self.n_jobs)(jobs)
  File "C:\Users\ssune\Documents\GitHub\learngenAI310\lib\site-packages\sklearn\utils\parallel.py", line 74, in __call__
    return super().__call__(iterable_with_config)
  File "C:\Users\ssune\Documents\GitHub\learngenAI310\lib\site-packages\joblib\parallel.py", line 1918, in __call__
    return output if self.return_generator else list(output)
  File "C:\Users\ssune\Documents\GitHub\learngenAI310\lib\site-packages\joblib\parallel.py", line 1847, in _get_sequential_output
    res = func(*args, **kwargs)
  File "C:\Users\ssune\Documents\GitHub\learngenAI310\lib\site-packages\sklearn\utils\parallel.py", line 136, in __call__
    return self.function(*args, **kwargs)
  File "C:\Users\ssune\Documents\GitHub\learngenAI310\lib\site-packages\sklearn\pipeline.py", line 1290, in _transform_one
    res = transformer.transform(X, **params.transform)
  File "C:\Users\ssune\Documents\GitHub\learngenAI310\lib\site-packages\sklearn\pipeline.py", line 903, in transform
    Xt = transform.transform(Xt, **routed_params[name].transform)
  File "C:\Users\ssune\Documents\GitHub\learngenAI310\lib\site-packages\sklearn\utils\_set_output.py", line 313, in wrapped
    data_to_wrap = f(self, X, *args, **kwargs)
  File "C:\Users\ssune\Documents\GitHub\learngenAI310\lib\site-packages\sklearn\preprocessing\_encoders.py", line 1033, in transform
    if self._drop_idx_after_grouping is not None:
AttributeError: 'OneHotEncoder' object has no attribute '_drop_idx_after_grouping'

During handling of the above exception, another exception occurred:

Traceback (most recent call last):
  File "C:\Users\ssune\Documents\GitHub\learngenAI310\lib\site-packages\flask\app.py", line 1473, in wsgi_app
    response = self.full_dispatch_request()
  File "C:\Users\ssune\Documents\GitHub\learngenAI310\lib\site-packages\flask\app.py", line 882, in full_dispatch_request
    rv = self.handle_user_exception(e)
  File "C:\Users\ssune\Documents\GitHub\learngenAI310\lib\site-packages\flask\app.py", line 880, in full_dispatch_request
    rv = self.dispatch_request()
  File "C:\Users\ssune\Documents\GitHub\learngenAI310\lib\site-packages\flask\app.py", line 865, in dispatch_request
    return self.ensure_sync(self.view_functions[rule.endpoint])(**view_args)  # type: ignore[no-any-return]
  File "C:\Users\ssune\Documents\GitHub\Complete-Data-Science-With-Machine-Learning-And-NLP-2024\mlProject\app.py", line 37, in predict_datapoint
    results=predict_pipeline.predict(pred_df)
  File "C:\Users\ssune\Documents\GitHub\Complete-Data-Science-With-Machine-Learning-And-NLP-2024\mlProject\src\pipeline\predict_pipeline.py", line 23, in predict
    raise CustomException(e,sys)
src.exception.CustomException: Error occured in python script name [C:\Users\ssune\Documents\GitHub\Complete-Data-Science-With-Machine-Learning-And-NLP-2024\mlProject\src\pipeline\predict_pipeline.py] line number [18] error message['OneHotEncoder' object has no attribute '_drop_idx_after_grouping']
[ 2024-09-09 11:49:21,363 ] 97 werkzeug - INFO - 127.0.0.1 - - [09/Sep/2024 11:49:21] "[35m[1mPOST /predictdata HTTP/1.1[0m" 500 -
